Workbook

Sheet 안내사항
A1: < 안내사항 > 1. 해당 양식은 온실가스 국제감축 투자지원사업 공고 신청기관의 국제감축실적 분배계획서 작성을 위한 보조자료입니다. 2. 해당 자료는 국제감축실적 분배계획서 작성을 위한 참고 및 보조 양식이며, 정확한 분배량 산정은 신청기관에서 관련규정(운영지침)을 확인하여 작성하시기 바랍니다. 3. 양식 내 노란색 칸에 해당하는 수치만을 입력해주십시오.

Sheet 금액방식-고정가격(일반)
B3: 고 정 가 격 (일반) | D3: 분배 연도 | E3: 예상 온실가스 감축량 | F3: 국제감축실적 (예상)발행량 | G3: 국내(예상) 분배량 (A) | H3: 투자지원금 상환액 | I3: 고시 가격 | J3: 수탁기관 (예상)분배량 (B) | K3: 비율 (A/B)
E6: (tCO2-eq) | F6: (tCO2-eq) | G6: (tCO2-eq) | H6: (억) | I6: (원) | J6: (tCO2-eq)
D7: 1차연도 | G7: =(G17/10) -> 0 | H7: =(H17/10) -> 0 | I7: ='수탁기관 분배량 시뮬레이션'!$D$25 -> 9452 | J7: ='수탁기관 분배량 시뮬레이션'!$L$30 -> 0 | K7: =(G7/J7) -> #DIV/0!
D8: 2차연도 | G8: =(G17/10) -> 0 | H8: =(H17/10) -> 0 | J8: ='수탁기관 분배량 시뮬레이션'!$L$30 -> 0 | K8: =(G8/J8) -> #DIV/0!
D9: 3차연도 | G9: =(G17/10) -> 0 | H9: =(H17/10) -> 0 | J9: ='수탁기관 분배량 시뮬레이션'!$L$30 -> 0 | K9: =(G9/J9) -> #DIV/0!
D10: 4차연도 | G10: =(G17/10) -> 0 | H10: =(H17/10) -> 0 | J10: ='수탁기관 분배량 시뮬레이션'!$L$30 -> 0 | K10: =(G10/J10) -> #DIV/0!
D11: 5차연도 | G11: =(G17/10) -> 0 | H11: =(H17/10) -> 0 | J11: ='수탁기관 분배량 시뮬레이션'!$L$30 -> 0 | K11: =(G11/J11) -> #DIV/0!
D12: 6차연도 | G12: =(G17/10) -> 0 | H12: =(H17/10) -> 0 | J12: ='수탁기관 분배량 시뮬레이션'!$L$30 -> 0 | K12: =(G12/J12) -> #DIV/0!
D13: 7차연도 | G13: =(G17/10) -> 0 | H13: =(H17/10) -> 0 | J13: ='수탁기관 분배량 시뮬레이션'!$L$30 -> 0 | K13: =(G13/J13) -> #DIV/0!
D14: 8차연도 | G14: =(G17/10) -> 0 | H14: =(H17/10) -> 0 | J14: ='수탁기관 분배량 시뮬레이션'!$L$30 -> 0 | K14: =(G14/J14) -> #DIV/0!
D15: 9차연도 | G15: =(G17/10) -> 0 | H15: =(H17/10) -> 0 | J15: ='수탁기관 분배량 시뮬레이션'!$L$30 -> 0 | K15: =(G15/J15) -> #DIV/0!
D16: 10차연도 | G16: =(G17/10) -> 0 | H16: =(H17/10) -> 0 | J16: ='수탁기관 분배량 시뮬레이션'!$L$30 -> 0 | K16: =(G16/J16) -> #DIV/0!
D17: 계 | E17: =SUM(E7:E16) -> 0 | F17: =SUM(F7:F16) -> 0 | G17: ='수탁기관 분배량 시뮬레이션'!$D$15 -> 0 | H17: =('수탁기관 분배량 시뮬레이션'!$D$13/100000000) -> 0 | J17: =SUM(J7:J16) -> 0

Sheet 금액방식-고정가격(절충)
B3: 고 정 가 격 (절충) | D3: 분배 연도 | E3: 예상 온실가스 감축량 | F3: 국제감축실적 (예상)발행량 | G3: 국내(예상) 분배량 (A) | H3: 투자지원금 상환액 | I3: 고시 가격 | J3: 수탁기관 (예상)분배량 (B) | K3: 비율 (A/B)
E6: (tCO2-eq) | F6: (tCO2-eq) | G6: (tCO2-eq) | H6: (억) | I6: (원) | J6: (tCO2-eq)
D7: 1차연도 | G7: =(G17/10) -> 0 | H7: =(H17/10) -> 0 | I7: ='수탁기관 분배량 시뮬레이션'!$D$36 -> 9452 | J7: ='수탁기관 분배량 시뮬레이션'!$L$46 -> 0
D8: 2차연도 | G8: =(G17/10) -> 0 | H8: =(H17/10) -> 0 | J8: ='수탁기관 분배량 시뮬레이션'!M$46 -> 0 | K8: =(G8/J8) -> #DIV/0!
D9: 3차연도 | G9: =(G17/10) -> 0 | H9: =(H17/10) -> 0 | J9: ='수탁기관 분배량 시뮬레이션'!N$46 -> 0 | K9: =(G9/J9) -> #DIV/0!
D10: 4차연도 | G10: =(G17/10) -> 0 | H10: =(H17/10) -> 0 | J10: ='수탁기관 분배량 시뮬레이션'!O$46 -> 0 | K10: =(G10/J10) -> #DIV/0!
D11: 5차연도 | G11: =(G17/10) -> 0 | H11: =(H17/10) -> 0 | J11: ='수탁기관 분배량 시뮬레이션'!P$46 -> 0 | K11: =(G11/J11) -> #DIV/0!
D12: 6차연도 | G12: =(G17/10) -> 0 | H12: =(H17/10) -> 0 | J12: ='수탁기관 분배량 시뮬레이션'!Q$46 -> 0 | K12: =(G12/J12) -> #DIV/0!
D13: 7차연도 | G13: =(G17/10) -> 0 | H13: =(H17/10) -> 0 | J13: ='수탁기관 분배량 시뮬레이션'!R$46 -> 0 | K13: =(G13/J13) -> #DIV/0!
D14: 8차연도 | G14: =(G17/10) -> 0 | H14: =(H17/10) -> 0 | J14: ='수탁기관 분배량 시뮬레이션'!S$46 -> 0 | K14: =(G14/J14) -> #DIV/0!
D15: 9차연도 | G15: =(G17/10) -> 0 | H15: =(H17/10) -> 0 | J15: ='수탁기관 분배량 시뮬레이션'!T$46 -> 0 | K15: =(G15/J15) -> #DIV/0!
D16: 10차연도 | G16: =(G17/10) -> 0 | H16: =(H17/10) -> 0 | J16: ='수탁기관 분배량 시뮬레이션'!U$46 -> 0 | K16: =(G16/J16) -> #DIV/0!
D17: 계 | E17: =SUM(E7:E16) -> 0 | F17: =SUM(F7:F16) -> 0 | G17: ='수탁기관 분배량 시뮬레이션'!$D$15 -> 0 | H17: ='수탁기관 분배량 시뮬레이션'!$D$13/100000000 -> 0 | J17: =SUM(J7:J16) -> 0

Sheet 금액방식-변동가격
B3: 변 동 가 격 | D3: 분배 연도 | E3: 예상 온실가스 감축량 | F3: 국제감축실적 (예상)발행량 | G3: 국내(예상) 분배량 (A) | H3: 투자지원금 상환액 | I3: 고시 가격 | J3: 수탁기관 (예상)분배량 (B) | K3: 비율 (A/B)
E6: (tCO2-eq) | F6: (tCO2-eq) | G6: (tCO2-eq) | H6: (원) | I6: (원) | J6: (tCO2-eq)
D7: 1차연도 | G7: =(G17/10) -> 0 | H7: =$H$17/10 -> 0 | I7: ='수탁기관 분배량 시뮬레이션'!D56 -> 0 | J7: ='수탁기관 분배량 시뮬레이션'!L$65 -> #DIV/0! | K7: =(G7/J7) -> #DIV/0!
D8: 2차연도 | G8: =(G17/10) -> 0 | H8: =$H$17/10 -> 0 | I8: ='수탁기관 분배량 시뮬레이션'!D57 -> 0 | J8: ='수탁기관 분배량 시뮬레이션'!M$65 -> #DIV/0! | K8: =(G8/J8) -> #DIV/0!
D9: 3차연도 | G9: =(G17/10) -> 0 | H9: =$H$17/10 -> 0 | I9: ='수탁기관 분배량 시뮬레이션'!D58 -> 0 | J9: ='수탁기관 분배량 시뮬레이션'!N65 -> #DIV/0! | K9: =(G9/J9) -> #DIV/0!
D10: 4차연도 | G10: =(G17/10) -> 0 | H10: =$H$17/10 -> 0 | I10: ='수탁기관 분배량 시뮬레이션'!D59 -> 0 | J10: ='수탁기관 분배량 시뮬레이션'!O65 -> #DIV/0! | K10: =(G10/J10) -> #DIV/0!
D11: 5차연도 | G11: =(G17/10) -> 0 | H11: =$H$17/10 -> 0 | I11: ='수탁기관 분배량 시뮬레이션'!D60 -> 0 | J11: ='수탁기관 분배량 시뮬레이션'!P65 -> #DIV/0! | K11: =(G11/J11) -> #DIV/0!
D12: 6차연도 | G12: =(G17/10) -> 0 | H12: =$H$17/10 -> 0 | I12: ='수탁기관 분배량 시뮬레이션'!D61 -> 0 | J12: ='수탁기관 분배량 시뮬레이션'!Q65 -> #DIV/0! | K12: =(G12/J12) -> #DIV/0!
D13: 7차연도 | G13: =(G17/10) -> 0 | H13: =$H$17/10 -> 0 | I13: ='수탁기관 분배량 시뮬레이션'!D62 -> 0 | J13: ='수탁기관 분배량 시뮬레이션'!R65 -> #DIV/0! | K13: =(G13/J13) -> #DIV/0!
D14: 8차연도 | G14: =(G17/10) -> 0 | H14: =$H$17/10 -> 0 | I14: ='수탁기관 분배량 시뮬레이션'!D63 -> 0 | J14: ='수탁기관 분배량 시뮬레이션'!S65 -> #DIV/0! | K14: =(G14/J14) -> #DIV/0!
D15: 9차연도 | G15: =(G17/10) -> 0 | H15: =$H$17/10 -> 0 | I15: ='수탁기관 분배량 시뮬레이션'!D64 -> 0 | J15: ='수탁기관 분배량 시뮬레이션'!T65 -> #DIV/0! | K15: =(G15/J15) -> #DIV/0!
D16: 10차연도 | G16: =(G17/10) -> 0 | H16: =$H$17/10 -> 0 | I16: ='수탁기관 분배량 시뮬레이션'!D65 -> 0 | J16: ='수탁기관 분배량 시뮬레이션'!U65 -> #DIV/0! | K16: =(G16/J16) -> #DIV/0!
D17: 계 | E17: =SUM(E7:E16) -> 0 | F17: =SUM(F7:F16) -> 0 | G17: ='수탁기관 분배량 시뮬레이션'!$D$15 -> 0 | H17: ='수탁기관 분배량 시뮬레이션'!$D$13/100000000 -> 0 | J17: =SUM(J7:J16) -> #DIV/0!

Sheet 지분방식
B3: 지 분 방 식 (예상) | D3: 분배 연도 | E3: 예상 온실가스 감축량 | F3: 국제감축실적 (예상)발행량 | G3: 국내(예상) 분배량 | H3: 정부부담률 | I3: 수탁기관 (예상) 분배량
E6: (tCO2-eq) | F6: (tCO2-eq) | G6: (tCO2-eq) | H6: (원) | I6: (tCO2-eq)
D7: 1차연도 | G7: =(G17/10) -> 0 | H7: ='수탁기관 분배량 시뮬레이션'!$D$13/'수탁기관 분배량 시뮬레이션'!$D$12 -> #DIV/0! | I7: =$G7*$H$7 -> #DIV/0!
D8: 2차연도 | G8: =(G17/10) -> 0 | I8: =$G8*$H$7 -> #DIV/0!
D9: 3차연도 | G9: =(G17/10) -> 0 | I9: =$G9*$H$7 -> #DIV/0!
D10: 4차연도 | G10: =(G17/10) -> 0 | I10: =$G10*$H$7 -> #DIV/0!
D11: 5차연도 | G11: =(G17/10) -> 0 | I11: =$G11*$H$7 -> #DIV/0!
D12: 6차연도 | G12: =(G17/10) -> 0 | I12: =$G12*$H$7 -> #DIV/0!
D13: 7차연도 | G13: =(G17/10) -> 0 | I13: =$G13*$H$7 -> #DIV/0!
D14: 8차연도 | G14: =(G17/10) -> 0 | I14: =$G14*$H$7 -> #DIV/0!
D15: 9차연도 | G15: =(G17/10) -> 0 | I15: =$G15*$H$7 -> #DIV/0!
D16: 10차연도 | G16: =(G17/10) -> 0 | I16: =$G16*$H$7 -> #DIV/0!
D17: 계 | E17: =SUM(E7:E16) -> 0 | F17: =SUM(F7:F16) -> 0 | G17: ='수탁기관 분배량 시뮬레이션'!$D$15 -> 0 | I17: =SUM(I7:I16) -> #DIV/0!
B21: 지 분 방 식 (실제) | D21: 분배 연도 | E21: 예상 온실가스 감축량 | F21: 국제감축실적 (실제)발행량 | G21: 국내(실제) 분배량 | H21: 정부부담률 | I21: 수탁기관 (실제) 분배량
E24: (tCO2-eq) | F24: (tCO2-eq) | G24: (tCO2-eq) | H24: (원) | I24: (tCO2-eq)
D25: 1차연도 | G25: ='수탁기관 분배량 시뮬레이션'!D83 -> 0 | H25: ='수탁기관 분배량 시뮬레이션'!$D$13/'수탁기관 분배량 시뮬레이션'!$D$12 -> #DIV/0! | I25: =$G25*$H$25 -> #DIV/0!
D26: 2차연도 | G26: ='수탁기관 분배량 시뮬레이션'!D84 -> 0 | I26: =$G26*$H$25 -> #DIV/0!
D27: 3차연도 | G27: ='수탁기관 분배량 시뮬레이션'!D85 -> 0 | I27: =$G27*$H$25 -> #DIV/0!
D28: 4차연도 | G28: ='수탁기관 분배량 시뮬레이션'!D86 -> 0 | I28: =$G28*$H$25 -> #DIV/0!
D29: 5차연도 | G29: ='수탁기관 분배량 시뮬레이션'!D87 -> 0 | I29: =$G29*$H$25 -> #DIV/0!
D30: 6차연도 | G30: ='수탁기관 분배량 시뮬레이션'!D88 -> 0 | I30: =$G30*$H$25 -> #DIV/0!
D31: 7차연도 | G31: ='수탁기관 분배량 시뮬레이션'!D89 -> 0 | I31: =$G31*$H$25 -> #DIV/0!
D32: 8차연도 | G32: ='수탁기관 분배량 시뮬레이션'!D90 -> 0 | I32: =$G32*$H$25 -> #DIV/0!
D33: 9차연도 | G33: ='수탁기관 분배량 시뮬레이션'!D91 -> 0 | I33: =$G33*$H$25 -> #DIV/0!
D34: 10차연도 | G34: ='수탁기관 분배량 시뮬레이션'!D92 -> 0 | I34: =$G34*$H$25 -> #DIV/0!
D35: 계 | E35: =SUM(E25:E34) -> 0 | F35: =SUM(F25:F34) -> 0 | G35: =SUM(G25:G34) -> 0 | I35: =SUM(I25:I34) -> #DIV/0!

Sheet 수탁기관 분배량 시뮬레이션
B1: DATA INPUT | I1: RESULT
B4: 공 통 사 항 [입 력]
B6: 항 목 | D6: 단위 (원, tCO2-eq)
B8: 감축설비 투자비 (직접비) | D8: 0
B10: 운영비 | D10: 0
B11: 기타 비용 | D11: 0
B12: 총사업비 (원) | D12: =(D8+D10+D11) -> 0
B13: 투자지원금 (원) | D13: 0
B14: 투자지원금 최대한도 (원) | D14: =(D8*0.5) -> 0
B15: 국내(예상) 총 분배량 (tCO2-eq) | D15: 0
B16: 최초 실적 발급연도 | D16: 2025
B19: 개 별 사 항 [입 력]
B21: 참 조 | C21: [고시가격] 직전 1년 평균 ('24) | D21: 9452
C22: [고시가격] 직전 3년 평균 ('22~'24) | D22: 11250
B24: 고 정 가 격 [일반] | C24: 협약 체결 시점 고시가격 | I24: 고 정 가 격 (일반) | J24: 단위 : (원, tCO2-eq) | V24: 지 원 금 합 계 및 환 산 금 액
B25: 2 | C25: 선 택 ▼ | D25: 9452 | J25: 분배연차 | L25: 1회차 | M25: 2회차 | N25: 3회차 | O25: 4회차 | P25: 5회차 | Q25: 6회차 | R25: 7회차 | S25: 8회차 | T25: 9회차 | U25: 10회차
J26: 분배연도 | L26: =($D$16)&" 년" -> 2025 년 | M26: =($D$16+1)&" 년" -> 2026 년 | N26: =($D$16+2)&" 년" -> 2027 년 | O26: =($D$16+3)&" 년" -> 2028 년 | P26: =($D$16+4)&" 년" -> 2029 년 | Q26: =($D$16+5)&" 년" -> 2030 년 | R26: =($D$16+6)&" 년" -> 2031 년 | S26: =($D$16+7)&" 년" -> 2032 년 | T26: =($D$16+8)&" 년" -> 2033 년 | U26: =($D$16+9)&" 년" -> 2034 년
J27: 연도별 국내(예상) 분배량 | L27: =$D$15/10 -> 0 | M27: =$D$15/10 -> 0 | N27: =$D$15/10 -> 0 | O27: =$D$15/10 -> 0 | P27: =$D$15/10 -> 0 | Q27: =$D$15/10 -> 0 | R27: =$D$15/10 -> 0 | S27: =$D$15/10 -> 0 | ... U27: =$D$15/10 -> 0
J28: 고정가격 | L28: =$D$25 -> 9452 | M28: =$D$25 -> 9452 | N28: =$D$25 -> 9452 | O28: =$D$25 -> 9452 | P28: =$D$25 -> 9452 | Q28: =$D$25 -> 9452 | R28: =$D$25 -> 9452 | S28: =$D$25 -> 9452 | ... U28: =$D$25 -> 9452
J29: 연도별 투자지원 상환금 | L29: =($D$13/10) -> 0 | M29: =($D$13/10) -> 0 | N29: =($D$13/10) -> 0 | O29: =($D$13/10) -> 0 | P29: =($D$13/10) -> 0 | Q29: =($D$13/10) -> 0 | R29: =($D$13/10) -> 0 | S29: =($D$13/10) -> 0 | ... U29: =($D$13/10) -> 0 | V29: =SUM(L29:U29) -> 0 | W29: 원
J30: 수탁기관 분배량 | K30: 연도별 수탁기관 분배량 | L30: =(L29/L28) -> 0 | M30: =(M29/M28) -> 0 | N30: =(N29/N28) -> 0 | O30: =(O29/O28) -> 0 | P30: =(P29/P28) -> 0 | Q30: =(Q29/Q28) -> 0 | R30: =(R29/R28) -> 0 | S30: =(S29/S28) -> 0 | ... U30: =(U29/U28) -> 0 | V30: II
K31: - 누적기간 환산량 | L31: =L30 -> 0 | M31: =M30+L31 -> 0 | N31: =N30+M31 -> 0 | O31: =O30+N31 -> 0 | P31: =P30+O31 -> 0 | Q31: =Q30+P31 -> 0 | R31: =R30+Q31 -> 0 | S31: =S30+R31 -> 0 | T31: =T30+S31 -> 0 | U31: =U30+T31 -> 0 | V31: =U31*U28 -> 0 | W31: 원
B35: 고 정 가 격 [절충] | C35: 협약 체결 시점 고시가격 | I35: 고 정 가 격 (절충) | J35: 단위 : (원, tCO2-eq) | V35: 지 원 금 합 계 및 환 산 금 액
C36: 선 택 ▼ | D36: 9452 | J36: 분배연차 | L36: 1회차 | M36: 2회차 | N36: 3회차 | O36: 4회차 | P36: 5회차 | Q36: 6회차 | R36: 7회차 | S36: 8회차 | T36: 9회차 | U36: 10회차
C37: [가격 절충 범위] 상승 시 | D37: =D36*1.3 -> 12287.6 | J37: 분배연도 | L37: =($D$16)&" 년" -> 2025 년 | M37: =($D$16+1)&" 년" -> 2026 년 | N37: =($D$16+2)&" 년" -> 2027 년 | O37: =($D$16+3)&" 년" -> 2028 년 | P37: =($D$16+4)&" 년" -> 2029 년 | Q37: =($D$16+5)&" 년" -> 2030 년 | R37: =($D$16+6)&" 년" -> 2031 년 | S37: =($D$16+7)&" 년" -> 2032 년 | T37: =($D$16+8)&" 년" -> 2033 년 | U37: =($D$16+9)&" 년" -> 2034 년
C38: [가격 절충 범위] 하락 시 | D38: =D36*0.7 -> 6616.4 | J38: 연도별 국내(예상) 분배량 | L38: =$D$15/10 -> 0 | M38: =$D$15/10 -> 0 | N38: =$D$15/10 -> 0 | O38: =$D$15/10 -> 0 | P38: =$D$15/10 -> 0 | Q38: =$D$15/10 -> 0 | R38: =$D$15/10 -> 0 | S38: =$D$15/10 -> 0 | ... U38: =$D$15/10 -> 0
C39: 실적 발급 시점의 국제감축실적 고시가격 | J39: 연도별 투자지원 상환금 | L39: =($D$13/10) -> 0 | M39: =($D$13/10) -> 0 | N39: =($D$13/10) -> 0 | O39: =($D$13/10) -> 0 | P39: =($D$13/10) -> 0 | Q39: =($D$13/10) -> 0 | R39: =($D$13/10) -> 0 | S39: =($D$13/10) -> 0 | ... U39: =($D$13/10) -> 0 | V39: =SUM(L39:U39) -> 0 | W39: 원
C40: [국제감축실적 가격] 1회차 (원) | D40: 0 | J40: 협약 체결 시점 고시가격 (A) | L40: =$D$36 -> 9452 | M40: =$D$36 -> 9452 | N40: =$D$36 -> 9452 | O40: =$D$36 -> 9452 | P40: =$D$36 -> 9452 | Q40: =$D$36 -> 9452 | R40: =$D$36 -> 9452 | S40: =$D$36 -> 9452 | ... U40: =$D$36 -> 9452
C41: [국제감축실적 가격] 2회차 | D41: 0 | J41: 연도별 국제감축실적 고시가격 (B) | L41: =$D40 -> 0 | M41: =$D41 -> 0 | N41: =D42 -> 0 | O41: =D43 -> 0 | P41: =D44 -> 0 | Q41: =D45 -> 0 | R41: =D46 -> 0 | S41: =D47 -> 0 | T41: =D48 -> 0 | U41: =D49 -> 0
C42: [국제감축실적 가격] 3회차 | D42: 0 | J42: 시장가격 분석 | K42: 고시가격 대비 변화율 (B/A) | L42: =L$41/L$40 -> 0 | M42: =M$41/M$40 -> 0 | N42: =N$41/N$40 -> 0 | O42: =O$41/O$40 -> 0 | P42: =P$41/P$40 -> 0 | Q42: =Q$41/Q$40 -> 0 | R42: =R$41/R$40 -> 0 | S42: =S$41/S$40 -> 0 | ... U42: =U$41/U$40 -> 0
C43: [국제감축실적 가격] 4회차 | D43: 0 | K43: 가격 절충 필요여부 | L43: =IF(AND(L$42>=70%,L$42<=130%),"X ","O") -> O | M43: =IF(AND(M$42>=70%,M$42<=130%),"X ","O") -> O | N43: =IF(AND(N$42>=70%,N$42<=130%),"X ","O") -> O | O43: =IF(AND(O$42>=70%,O$42<=130%),"X ","O") -> O | P43: =IF(AND(P$42>=70%,P$42<=130%),"X ","O") -> O | Q43: =IF(AND(Q$42>=70%,Q$42<=130%),"X ","O") -> O | R43: =IF(AND(R$42>=70%,R$42<=130%),"X ","O") -> O | S43: =IF(AND(S$42>=70%,S$42<=130%),"X ","O") -> O | ... U43: =IF(AND(U$42>=70%,U$42<=130%),"X ","O") -> O | V43: II
C44: [국제감축실적 가격] 5회차 | D44: 0 | K44: 가격 절충분 | L44: =IF(AND(L41>=L40*0.7,L41<=L40*1.3),0,IF(L41>=L40*1.3,(L41-L40*1.3)/2,IF(L41<=L40*0.7,(L41-L40*0.7)/2))) -> -3308.2 | M44: =IF(AND(M41>=M40*0.7,M41<=M40*1.3),0,IF(M41>=M40*1.3,(M41-M40*1.3)/2,IF(M41<=M40*0.7,(M41-M40*0.7)/2))) -> -3308.2 | N44: =IF(AND(N41>=N40*0.7,N41<=N40*1.3),0,IF(N41>=N40*1.3,(N41-N40*1.3)/2,IF(N41<=N40*0.7,(N41-N40*0.7)/2))) -> -3308.2 | O44: =IF(AND(O41>=O40*0.7,O41<=O40*1.3),0,IF(O41>=O40*1.3,(O41-O40*1.3)/2,IF(O41<=O40*0.7,(O41-O40*0.7)/2))) -> -3308.2 | P44: =IF(AND(P41>=P40*0.7,P41<=P40*1.3),0,IF(P41>=P40*1.3,(P41-P40*1.3)/2,IF(P41<=P40*0.7,(P41-P40*0.7)/2))) -> -3308.2 | Q44: =IF(AND(Q41>=Q40*0.7,Q41<=Q40*1.3),0,IF(Q41>=Q40*1.3,(Q41-Q40*1.3)/2,IF(Q41<=Q40*0.7,(Q41-Q40*0.7)/2))) -> -3308.2 | R44: =IF(AND(R41>=R40*0.7,R41<=R40*1.3),0,IF(R41>=R40*1.3,(R41-R40*1.3)/2,IF(R41<=R40*0.7,(R41-R40*0.7)/2))) -> -3308.2 | S44: =IF(AND(S41>=S40*0.7,S41<=S40*1.3),0,IF(S41>=S40*1.3,(S41-S40*1.3)/2,IF(S41<=S40*0.7,(S41-S40*0.7)/2))) -> -3308.2 | ... U44: =IF(AND(U41>=U40*0.7,U41<=U40*1.3),0,IF(U41>=U40*1.3,(U41-U40*1.3)/2,IF(U41<=U40*0.7,(U41-U40*0.7)/2))) -> -3308.2
C45: [국제감축실적 가격] 6회차 | D45: 0 | J45: 장기고정가격(절충) | L45: =L40+L44 -> 6143.8 | M45: =M40+M44 -> 6143.8 | N45: =N40+N44 -> 6143.8 | O45: =O40+O44 -> 6143.8 | P45: =P40+P44 -> 6143.8 | Q45: =Q40+Q44 -> 6143.8 | R45: =R40+R44 -> 6143.8 | S45: =S40+S44 -> 6143.8 | ... U45: =U40+U44 -> 6143.8
C46: [국제감축실적 가격] 7회차 | D46: 0 | J46: 수탁기관 분배량 | K46: 연도별 수탁기관 분배량 | L46: =(L$39/L$45) -> 0 | M46: =(M$39/M$45) -> 0 | N46: =(N$39/N$45) -> 0 | O46: =(O$39/O$45) -> 0 | P46: =(P$39/P$45) -> 0 | Q46: =(Q$39/Q$45) -> 0 | R46: =(R$39/R$45) -> 0 | S46: =(S$39/S$45) -> 0 | ... U46: =(U$39/U$45) -> 0 | V46: =L46*L45+M46*M45+N46*N45+O46*O45+P46*P45+Q46*Q45+R46*R45+S46*S45+T46*T45+U46*U45 -> 0 | W46: 원
C47: [국제감축실적 가격] 8회차 | D47: 0 | K47: - 누적기간 환산량 | L47: =L46 -> 0 | M47: =M46+L47 -> 0 | N47: =N46+M47 -> 0 | O47: =O46+N47 -> 0 | P47: =P46+O47 -> 0 | Q47: =Q46+P47 -> 0 | R47: =R46+Q47 -> 0 | S47: =S46+R47 -> 0 | T47: =T46+S47 -> 0 | U47: =U46+T47 -> 0
C48: [국제감축실적 가격] 9회차 | D48: 0
C49: [국제감축실적 가격] 10회차 | D49: 0
B53: 변 동 가 격 | I53: 변 동 가 격 | J53: 단위 : (원, tCO2-eq) | V53: 지 원 금 합 계 및 환 산 금 액 | Z53: 변 동 가 격 | AA53: 단위 : (원, tCO2-eq) | AM53: 지 원 금 합 계 및 환 산 금 액
C54: 총 투자지원금 지급완료 시점1) | D54: 45658 | J54: 분배회차 및 연도 | L54: ="1회차 ('"&YEAR(D66)-2000&"년)" -> 1회차 ('25년) | M54: ="2회차 ('"&YEAR(D67)-2000&"년)" -> 2회차 ('25년) | N54: ="3회차 ('"&YEAR(D68)-2000&"년)" -> 3회차 ('25년) | O54: ="4회차 ('"&YEAR(D69)-2000&"년)" -> 4회차 ('25년) | P54: ="5회차 ('"&YEAR(D70)-2000&"년)" -> 5회차 ('25년) | Q54: ="6회차 ('"&YEAR(D71)-2000&"년)" -> 6회차 ('25년) | R54: ="7회차 ('"&YEAR(D72)-2000&"년)" -> 7회차 ('25년) | S54: ="8회차 ('"&YEAR(D73)-2000&"년)" -> 8회차 ('25년) | T54: ="9회차 ('"&YEAR(D74)-2000&"년)" -> 9회차 ('25년) | U54: ="10회차 ('"&YEAR(D75)-2000&"년)" -> 10회차 ('25년) | AA54: 분배연차 | AC54: 1회차 | AD54: 2회차 | AE54: 3회차 | AF54: 4회차 | AG54: 5회차 | AH54: 6회차 | AI54: 7회차 | AJ54: 8회차 | AK54: 9회차 | AL54: 10회차
C55: 적용 양식 | D55: [양식1] | F55: [양식2] | J55: 경과일수 (일) | L55: =IF(D66-$D$54>0, D66-$D$54, "소급 적용") -> 64 | M55: =D67-$D$54 -> 64 | N55: =D68-$D$54 -> 64 | O55: =D69-$D$54 -> 64 | P55: =D70-$D$54 -> 64 | Q55: =D71-$D$54 -> 64 | R55: =D72-$D$54 -> 64 | S55: =D73-$D$54 -> 64 | T55: =D74-$D$54 -> 64 | U55: =D75-$D$54 -> 64 | AA55: 분배연도 | AC55: =($D$16)&" 년" -> 2025 년 | AD55: =($D$16+1)&" 년" -> 2026 년 | AE55: =($D$16+2)&" 년" -> 2027 년 | AF55: =($D$16+3)&" 년" -> 2028 년 | AG55: =($D$16+4)&" 년" -> 2029 년 | AH55: =($D$16+5)&" 년" -> 2030 년 | AI55: =($D$16+6)&" 년" -> 2031 년 | AJ55: =($D$16+7)&" 년" -> 2032 년 | AK55: =($D$16+8)&" 년" -> 2033 년 | AL55: =($D$16+9)&" 년" -> 2034 년
...

Sheet 산출 Sheet
A2: [대표금리] 1회차 (YYYY-MM-DD, %) | B2: ='수탁기관 분배량 시뮬레이션'!$D66 -> 45722 | C2: =EDATE($B2,-12) -> 45357 | D2: =B2-C2 -> 365
A3: [대표금리] 2회차 (YYYY-MM-DD, %) | B3: ='수탁기관 분배량 시뮬레이션'!$D67 -> 45722 | C3: =EDATE($B3,-12) -> 45357 | D3: =B3-C3 -> 365
A4: [대표금리] 3회차 (YYYY-MM-DD, %) | B4: ='수탁기관 분배량 시뮬레이션'!$D68 -> 45722 | C4: =EDATE($B4,-12) -> 45357 | D4: =B4-C4 -> 365
A5: [대표금리] 4회차 (YYYY-MM-DD, %) | B5: ='수탁기관 분배량 시뮬레이션'!$D69 -> 45722 | C5: =EDATE($B5,-12) -> 45357 | D5: =B5-C5 -> 365
A6: [대표금리] 5회차 (YYYY-MM-DD, %) | B6: ='수탁기관 분배량 시뮬레이션'!$D70 -> 45722 | C6: =EDATE($B6,-12) -> 45357 | D6: =B6-C6 -> 365
A7: [대표금리] 6회차 (YYYY-MM-DD, %) | B7: ='수탁기관 분배량 시뮬레이션'!$D71 -> 45722 | C7: =EDATE($B7,-12) -> 45357 | D7: =B7-C7 -> 365
A8: [대표금리] 7회차 (YYYY-MM-DD, %) | B8: ='수탁기관 분배량 시뮬레이션'!$D72 -> 45722 | C8: =EDATE($B8,-12) -> 45357 | D8: =B8-C8 -> 365
A9: [대표금리] 8회차 (YYYY-MM-DD, %) | B9: ='수탁기관 분배량 시뮬레이션'!$D73 -> 45722 | C9: =EDATE($B9,-12) -> 45357 | D9: =B9-C9 -> 365
A10: [대표금리] 9회차 (YYYY-MM-DD, %) | B10: ='수탁기관 분배량 시뮬레이션'!$D74 -> 45722 | C10: =EDATE($B10,-12) -> 45357 | D10: =B10-C10 -> 365
A11: [대표금리] 10회차 (YYYY-MM-DD, %) | B11: ='수탁기관 분배량 시뮬레이션'!$D75 -> 45722 | C11: =EDATE($B11,-12) -> 45357 | D11: =B11-C11 -> 365
